Workbook

Sheet Planilha Custos
A2: PLANILHA DE CUSTOS
A6: Qtde. | B6: Estrutura
A7: 2 | B7: Municípios de Rio Branco e Cruzeiro do Sul | F7: =94*45% -> 42.3
A8: =Escolas!A16 -> 14 | B8: Escola
A9: =Escolas!H17 -> 16 | B9: Professores de Educação Física
A10: =Escolas!E17 -> 14 | B10: Gestores
A11: =Escolas!F17 -> 56 | B11: Coordenadores de Área
A12: =Escolas!G17 -> 14 | B12: Coordenadores de Ensino
A13: =Escolas!D17 -> 7116 | B13: Alunos
A17: LEVANTAMENTO DE DADOS
A18: Itens | B18: Levantamento de Dados | C18: Unidade | D18: quantidade | F18: Valor Unitário | G18: Valor Total
A19: 1 | B19: Levantamento Situacional: Esta etapa compreende a realização de levantamento situacional das Escolas em que o público alvo está matriculado | C19: unidade | D19: 1 | F19: =85000+60000+67310.03 -> 212310.03 | G19: =F19*D19 -> 212310.03
A20: 2 | B20: Protocolo de diagnóstico das capacidades físicas, de saúde, psicossociais e vocação esportiva, com estudos técnicos das métricas e potencilalidade dos alunos de acordo com suas caracteristicas e aptidões esportivas e vocacionais. | C20: Serviço | D20: =A13 -> 7116 | F20: 132 | G20: =D20*F20 -> 939312
A21: 3 | B21: Pesquisa Científica | C21: Serviço | D21: 1 | F21: =334975.29-6926.95 -> 328048.34 | G21: =D21*F21 -> 328048.34
B22: SUB-TOTAL | G22: =SUM(G19:G21) -> 1479670.4
A24: MATERIAIS PEDAGÓGICOS E SISTEMA EAD
A25: Itens | B25: CURSOS DE FORMAÇÃO | C25: Unidade | D25: quantidade | F25: Valor Unitário | G25: Valor Total
A26: 4 | B26: Apresentação Metodologia (Presencial - Carga Horária 4 horas) | C26: disponibilizaçao de curso | D26: =A9+A10+A11+A12 -> 100 | F26: 250 | G26: =D26*F26 -> 25000
A27: 5 | B27: Tecnologia e Desenvolvimento Talentos Esportivo (EAD / Carga Horária de 40 Horas) | C27: disponibilizaçao de curso | D27: =A9+A10 -> 30 | F27: 250 | G27: =D27*F27 -> 7500
A28: 6 | B28: Promoção e Defesa dos Direitos da Criança e do Adolescente (EAD / Carga Horária de 40 Horas) | C28: disponibilizaçao de curso | D28: =A9+A10 -> 30 | F28: 250 | G28: =D28*F28 -> 7500
A29: 7 | B29: Temas Transversais (Agenda 2030 – ODS/ONU e BNCC) (EAD / Carga Horária de 40 Horas) - PROFESSORES | C29: disponibilizaçao de curso | D29: =A9+A10 -> 30 | F29: 250 | G29: =D29*F29 -> 7500
A30: 8 | B30: Temas Transversais (Agenda 2030 – ODS/ONU e BNCC) (EAD / Carga Horária de 40 Horas) - ALUNOS | C30: disponibilizaçao de curso | D30: =A13*25% -> 1779 | F30: 250 | G30: =D30*F30 -> 444750
A31: 9 | B31: Pós-Graduação em Detecção e Desenvolvimento de Talentos Esportivos na Infância e Adolescência – Reconhecido pelo MEC. (EAD / Carga Horária de 360 Horas). | C31: disponibilizaçao de curso | D31: =A9+A10 -> 30 | F31: 2800 | G31: =D31*F31 -> 84000
A32: 10 | B32: Oficinas de Qualificação Social | C32: disponibilizaçao de curso | D32: 1500 | F32: 250 | G32: =D32*F32 -> 375000
A33: 11 | B33: Palestras de Capacitação | C33: diária | D33: 6 | E33: 2 | F33: 5000 | G33: =D33*F33 -> 30000
A34: 12 | B34: Palestrante Regional: Palestras de conscientização/motivacionais nas escolas | C34: diária | D34: =A8*3 -> 42 | F34: 1500 | G34: =D34*F34 -> 63000
A35: 13 | B35: A Olimpíada do Saber, Esporte e Educação: Plataforma para estudantes das escolas participantes, atividades de gamificação para estimular a competição saudável e o aprimoramento acadêmico, interativo para engajamento dos alunos. Aplicação de testes/ provas que abordarão temas ligados às mais diversas modalidades esportivas, bem como suas correlações com diversas áreas do conhecimento. | C35: Disponibilização | D35: 1 | F35: 259730 | G35: =D35*F35 -> 259730
A36: 14 | B36: Cursos Preparatório para Pré-Vestibular | C36: disponibilizaçao de curso | D36: =A13*25% -> 1779 | F36: 250 | G36: =D36*F36 -> 444750
A37: 15 | B37: Curso de Educação Financeira | C37: disponibilizaçao de curso | D37: 1500 | F37: 250 | G37: =D37*F37 -> 375000
B38: TOTAL FORMAÇÃO | G38: =SUM(G26:G37) -> 2123730
A40: SISTEMA DE TECNOLOGIA
A41: Itens | B41: Sistema Tecnológico | C41: Unidade | D41: quantidade | F41: Valor Unitário | G41: Valor Total
A42: 17 | B42: Sistema de gestão da Informação e Indicadores Sociais. Plataformas digitais e Business Intelligence (B.I.) aptas à coleta e interpretação de métricas relacionadas as escolas de EMTI, bem como do acompanhamento sistemático dos alunos, garantindo que as informações não se percam e sejam de fácil acesso para ambas as partes; | C42: serviço | D42: 1 | F42: =A13*5.1*12 -> 435499.2 | G42: =F42*D42 -> 435499.2
A43: 18 | B43: Impressão de Carteirinha para identificação dos alunos. Produzida em PVC compactado 4/4 cores de 1mm. | C43: serviço | D43: =A13 -> 7116 | F43: 12.5 | G43: =D43*F43*2 -> 177900
B44: SUB-TOTAL | G44: =SUM(G42:G43) -> 613399.2
A46: AQUISIÇÃO DE MATERIAIS E EQUIPAMENTOS
A48: MATERIAIS ESPORTIVOS
A49: Itens | B49: MATERIAIS ESPORTIVOS | C49: Unidade | D49: quantidade | F49: Valor Unitário | G49: Valor Total
A50: 19 | B50: Bola de Basquete Adulto - Bola oficial de basquetebol, tamanho masculino, matrizada, confeccionada com borracha, câmara airbility, miolo slip system removível e lubrifica do tamanho 7 com 74,9 cm de diâmetro, pesando entre 567 e 624 gramas, | C50: UNI | D50: =$A$8*6 -> 84 | F50: 129.9 | G50: =D50*F50 -> 10911.6
A51: 20 | B51: Bola de Basquete Infantil Bola de Basquete (tamanho mirim), matrizada, confeccionada em borracha, câmara de ar em butil miolo de válvula removível peso aproximado: 300 a 500 gramas, Medida aproximada de circunferência 60 a 74cm. | C51: UNI | D51: =$A$8*6 -> 84 | F51: 129.9 | G51: =D51*F51 -> 10911.6
...

Sheet Cronograma
A2: CRONOGRAMA DE DESEMBOLSO
A4: AÇÕES | B4: 1ª DESEMBOLSO | C4: 2ª DESEMBOLSO | D4: 3ª DESEMBOLSO | E4: 4ª DESEMBOLSO | F4: 5ª DESEMBOLSO | G4: 6ª DESEMBOLSO | H4: 7ª DESEMBOLSO | I4: 8ª DESEMBOLSO | J4: 9ª DESEMBOLSO | K4: 10ª DESEMBOLSO | L4: 11ª DESEMBOLSO | M4: 12ª DESEMBOLSO | N4: TOTAL
A6: LEVANTAMENTO DE DADOS
A7: Levantamento Situacional | C7: ='Planilha Custos'!G19/2 -> 106155.01 | D7: =C7 -> 106155.01 | N7: =SUM(B7:M7) -> 212310.03
A8: Protocolo Avaliativo | D8: ='Planilha Custos'!G20/2 -> 469656 | E8: =D8 -> 469656 | N8: =SUM(B8:M8) -> 939312
A9: Pesquisa Científica | B9: ='Planilha Custos'!G21/12 -> 27337.362 | C9: =B9 -> 27337.362 | D9: =C9 -> 27337.362 | E9: =D9 -> 27337.362 | F9: =E9 -> 27337.362 | G9: =F9 -> 27337.362 | H9: =G9 -> 27337.362 | I9: =H9 -> 27337.362 | J9: =I9 -> 27337.362 | ... M9: =L9 -> 27337.362 | N9: =SUM(B9:M9) -> 328048.34
N10: =SUM(B10:M10) -> 0
A11: MATERIAIS PEDAGÓGICOS E SISTEMA EAD | G11: =B11 -> 0 | N11: =SUM(B11:M11) -> 0
A12: Apresentação da Metodologia | B12: ='Planilha Custos'!G26 -> 25000 | N12: =SUM(B12:M12) -> 25000
A13: Tecnologia e Desenvolvimento Talentos | B13: ='Planilha Custos'!G27 -> 7500 | N13: =SUM(B13:M13) -> 7500
A14: Promoção e Defesa dos Direitos da Criança | B14: ='Planilha Custos'!G28 -> 7500 | N14: =SUM(B14:M14) -> 7500
A15: Temas Transversais - Professores | B15: ='Planilha Custos'!G29 -> 7500 | N15: =SUM(B15:M15) -> 7500
A16: Pós-Gradução | B16: ='Planilha Custos'!G31 -> 84000 | N16: =SUM(B16:M16) -> 84000
A17: Palestra Capacitação | B17: 5000 | D17: 5000 | F17: 5000 | H17: 5000 | J17: 5000 | L17: 5000 | N17: =SUM(B17:M17) -> 30000
A18: Palestrante Regional | E18: ='Planilha Custos'!G34/4 -> 15750 | G18: =E18 -> 15750 | I18: =G18 -> 15750 | L18: =I18 -> 15750 | N18: =SUM(B18:M18) -> 63000
A19: Olimpíadas do Saber | B19: ='Planilha Custos'!G35 -> 259730 | N19: =SUM(B19:M19) -> 259730
A20: Oficinas de Qualificação Social | B20: ='Planilha Custos'!G32 -> 375000 | N20: =SUM(B20:M20) -> 375000
A21: Temas Transversais - Alunos | B21: ='Planilha Custos'!G30 -> 444750 | N21: =SUM(B21:M21) -> 444750
A22: ='Planilha Custos'!B36 -> Cursos Preparatório para Pré-Vestibular | B22: ='Planilha Custos'!G36 -> 444750 | N22: =SUM(B22:M22) -> 444750
A23: ='Planilha Custos'!B37 -> Curso de Educação Financeira | B23: ='Planilha Custos'!G37 -> 375000 | N23: =SUM(B23:M23) -> 375000
A24: Materiais Pegagógicos | B24: =('Planilha Custos'!F168)/3 -> 410949 | E24: =B24*2 -> 821898 | N24: =SUM(B24:M24) -> 1232847
N25: =SUM(B25:M25) -> 0
A26: SISTEMA TECNOLOGIA | N26: =SUM(B26:M26) -> 0
A27: Sistema de Gestão | B27: ='Planilha Custos'!G44 -> 613399.2 | N27: =SUM(B27:M27) -> 613399.2
N28: =SUM(B28:M28) -> 0
A29: AQUISIÇÃO DE MATERIAIS | N29: =SUM(B29:M29) -> 0
A30: Materiais Esportivos | C30: ='Planilha Custos'!G78 -> 287959 | N30: =SUM(B30:M30) -> 287959
A31: Materiais para Avaliação do Alunos | C31: ='Planilha Custos'!G95 -> 70676.55 | N31: =SUM(B31:M31) -> 70676.55
A32: Kit Alunos | C32: ='Planilha Custos'!G102 -> 267587.1 | N32: =SUM(B32:M32) -> 267587.1
N33: =SUM(B33:M33) -> 0
A34: CAMPANHA SOCIAL | N34: =SUM(B34:M34) -> 0
A35: Comunicação | C35: ='Planilha Custos'!G107 -> 148000 | N35: =SUM(C35:M35) -> 148000
A36: Assessoria de Imprensa | B36: ='Planilha Custos'!G108/12 -> 6000 | C36: =B36 -> 6000 | D36: =C36 -> 6000 | E36: =D36 -> 6000 | F36: =E36 -> 6000 | G36: =F36 -> 6000 | H36: =G36 -> 6000 | I36: =H36 -> 6000 | J36: =I36 -> 6000 | ... M36: =L36 -> 6000 | N36: =SUM(B36:M36) -> 72000
A37: Criação e produção de vídeo institucional | E37: ='Planilha Custos'!G109 -> 82500 | N37: =SUM(B37:M37) -> 82500
A38: Materiais Gráficos (impressões) | C38: ='Planilha Custos'!G112+'Planilha Custos'!G113+'Planilha Custos'!G114+'Planilha Custos'!G115+'Planilha Custos'!G116+'Planilha Custos'!G117+('Planilha Custos'!G118/2)+('Planilha Custos'!G119/2)+('Planilha Custos'!G120/3) -> 301510.4 | E38: =('Planilha Custos'!G110/2)+('Planilha Custos'!G111/2) -> 17654 | H38: =E38+('Planilha Custos'!G119/2)+('Planilha Custos'!G118/2)+('Planilha Custos'!G120/3) -> 218325.2 | K38: ='Planilha Custos'!G120/3 -> 8539.2 | N38: =SUM(B38:M38) -> 546028.8
A39: Evento Lançamento Programa | C39: ='Planilha Custos'!G131 -> 166266.1 | N39: =SUM(B39:M39) -> 166266.1
N40: =SUM(B40:M40) -> 0
A41: EVENTOS ESPORTIVOS | N41: =SUM(B41:M41) -> 0
A42: Eventos Esportivos/Logística | E42: =('Planilha Custos'!G135)/3 -> 62011.46 | H42: =E42 -> 62011.46 | K42: =H42 -> 62011.46 | N42: =SUM(B42:M42) -> 186034.38
A43: Logística | B43: ='Planilha Custos'!G147/12 -> 40833.333 | C43: =B43 -> 40833.333 | D43: =C43 -> 40833.333 | E43: =D43 -> 40833.333 | F43: =E43 -> 40833.333 | G43: =F43 -> 40833.333 | H43: =G43 -> 40833.333 | I43: =H43 -> 40833.333 | J43: =I43 -> 40833.333 | ... M43: =L43 -> 40833.333 | N43: =SUM(B43:M43) -> 490000
...

Sheet RH - Equipe Técnica
B6: ITENS | C6: EQUIPE DE PROFISSIONAIS | D6: QTDE. PROFISSIONAIS
B7: 1 | C7: Gestor de Projetos | D7: 1
B8: 2 | C8: Coordenador Regional | D8: 1
B9: 3 | C9: Coordenador Metodologia (Educação Física) | D9: 1
B10: 4 | C10: Coordenador Pedagógico | D10: 1
C11: EQUIPE MULTIDISCIPLINAR
B12: 5 | C12: Coordenador Metodologia (Educação Física) | D12: 3
B13: 6 | C13: Pedagogo | D13: 2
B14: 7 | C14: Psicólogo | D14: 2
B15: 8 | C15: Assistente Social | D15: 2
B16: 9 | C16: Nutricionista | D16: 2
B17: 10 | C17: Dentista | D17: 2
B18: 11 | C18: Monitor | D18: 10
C19: TOTAL | D19: 27

Sheet Escolas
A2: Nº | B2: Escolas | C2: Municípios | D2: Total geral de alunos | E2: Quantidade de Gestores | F2: Quantidade de Coordenadores de Área | G2: Quantidade de Coordenadores de Ensino | H2: Professores de Educação Física | I2: Quantidade de Assistentes Sociais e Psicólogos | J2: Localização/Endereço | K2: Quadra | L2: Sala de Informática
A3: 1 | B3: Escola Craveiro Costa | C3: Cruzeiro do Sul | D3: 709 | E3: 1 | F3: 4 | G3: 1 | H3: 1 | I3: 0
A4: 2 | B4: Escola Dom Henrique Ruht | C4: Cruzeiro do Sul | D4: 868 | E4: 1 | F4: 4 | G4: 1 | H4: 1 | I4: 0
A5: 3 | B5: Escola Flodoardo Cabral | C5: Cruzeiro do Sul | D5: 883 | E5: 1 | F5: 4 | G5: 1 | H5: 1 | I5: 0
A6: 4 | B6: Escola Boa União Ensino Jovem | C6: Rio Branco | D6: 360 | E6: 1 | F6: 4 | G6: 1 | H6: 1 | I6: 0 | J6: Rua Três de Agosto, n° 38, Boa União - Sobral. | K6: SIM | L6: SIM
A7: 5 | B7: Colégio Estadual Barão do Rio Branco | C7: Rio Branco | D7: 761 | E7: 1 | F7: 4 | G7: 1 | H7: 1 | I7: 0 | J7: Avenida Getúlio Vargas, n° 443 - Centro. | K7: SIM | L7: SIM
A8: 6 | B8: Escola Dr. João Batista Aguiar | C8: Rio Branco | D8: 441 | E8: 1 | F8: 4 | G8: 1 | H8: 1 | I8: 0 | J8: Rua Aderbal Brasil da Silva, n° 310 - Bairro Manoel Julião. | K8: SIM | L8: SIM
A9: 7 | B9: Escola Glória Perez | C9: Rio Branco | D9: 440 | E9: 1 | F9: 4 | G9: 1 | H9: 1 | I9: 0 | J9: Avenida Brasil, n° 85, Xavier Maia - Bairro Placas. | K9: SIM | L9: SIM
A10: 8 | B10: Escola Humberto Soares da Costa | C10: Rio Branco | D10: 397 | E10: 1 | F10: 4 | G10: 1 | H10: 1 | I10: 0 | J10: Rua Riachuelo, S/N° - Bairro José Augusto. | K10: SIM | L10: SIM
A11: 9 | B11: Instituto de Educação Lourenço Filho | C11: Rio Branco | D11: 430 | E11: 1 | F11: 4 | G11: 1 | H11: 1 | I11: 0 | J11: Avenida Getúlio Vargas, n° 2855 - Bairro Bosque. | K11: SIM | L11: SIM
A12: 10 | B12: Escola Ester Maia de Oliveira | C12: Rio Branco | D12: 172 | E12: 1 | F12: 4 | G12: 1 | H12: 1 | I12: 0 | J12: Avenida Jorge Cardoso, S/N° - Cidade do Povo. | K12: SIM | L12: SIM
A13: 11 | B13: Escola Jornalista Armando Nogueira | C13: Rio Branco | D13: 327 | E13: 1 | F13: 4 | G13: 1 | H13: 1 | I13: 0 | J13: Estrada Dias Martins, n° 1494 - Distrito Insdustrial. | K13: SIM | L13: SIM
A14: 12 | B14: Escola José Ribamar Batista | C14: Rio Branco | D14: 538 | E14: 1 | F14: 4 | G14: 1 | H14: 2 | I14: 0 | J14: Rua Rio Grande do Sul, 2570 - Bairro Aeroporto Velho. | K14: SIM | L14: SIM
A15: 13 | B15: Escola Prof. Pedro Martinello | C15: Rio Branco | D15: 381 | E15: 1 | F15: 4 | G15: 1 | H15: 1 | I15: 0 | J15: Avenida Antônio Pessoa Jucá, S/N - Bairro Tancredo Neves. | K15: SIM | L15: SIM
A16: 14 | B16: Escola Sebastião Pedrosa | C16: Rio Branco | D16: 409 | E16: 1 | F16: 4 | G16: 1 | H16: 2 | I16: 0 | J16: Travessa Comara, n° 101 - Bairro Comara. | K16: SIM | L16: SIM
A17: Total | D17: =SUM(D3:D16) -> 7116 | E17: =SUM(E3:E16) -> 14 | F17: =SUM(F3:F16) -> 56 | G17: =SUM(G3:G16) -> 14 | H17: =SUM(H3:H16) -> 16 | I17: =SUM(I3:I16) -> 0
